Workbook
Name ForecastMonth: 'Cash Flow Forecast'!$B$4
Name OpeningBalance: 'Cash Flow Forecast'!$E$4
Name ClosingEffectiveBalance: 'Cash Flow Forecast'!$C$40

Sheet Budget
A1: Household Budget
A2: Fill in the yellow cells. Day of Month is optional — set it to feed the Cash Flow Forecast sheet.
A4: Category | B4: Item | C4: Monthly Amount | D4: Day of Month | E4: Notes
A5: INCOME
A6: Income | B6: Household member 1 (take-home) | C6: 0 | E6: Fill in
A7: Income | B7: Household member 2 (take-home) | C7: 0 | E7: Fill in
A8: Income | B8: Other income | C8: 0 | E8: e.g. side income, bonuses
A9: Income | C9: 0
A10: Income | C10: 0
A11: Income | C11: 0
A12: Total Income | C12: =SUM(C6:C11)
A14: HOUSING
A15: Housing | B15: Rent / Mortgage | C15: 0 | E15: Fill in
A16: Housing | B16: Other housing costs | C16: 0 | E16: e.g. service charge, maintenance
A17: Total Housing | C17: =SUM(C15:C16)
A19: UTILITIES & INSURANCE
A20: Utilities | B20: Electricity | C20: 64
A21: Utilities | B21: WiFi | C21: 22
A22: Insurance | B22: Home insurance | C22: 23
A23: Insurance | B23: Vet insurance | C23: 30
A24: Total Utilities & Insurance | C24: =SUM(C20:C23)
A26: TRANSPORT
A27: Transport | B27: Car expenses | C27: 142
A28: Transport | B28: Car expenses | C28: 100
A29: Total Transport | C29: =SUM(C27:C28)
A31: SUBSCRIPTIONS
A32: Subscriptions | B32: Spotify | C32: 18
A33: Subscriptions | B33: Netflix | C33: 6
A34: Subscriptions | B34: Amazon | C34: 8.99
A35: Subscriptions | B35: Apple | C35: 3
A36: Subscriptions | B36: Google | C36: 2
A37: Subscriptions | B37: TV licence | C37: 15
A38: Subscriptions | B38: AWS | C38: 5
A39: Total Subscriptions | C39: =SUM(C32:C38)
A41: PERSONAL & OTHER
A42: Personal | B42: Nathan | C42: 150
A43: Personal | B43: Swimming | C43: 45
A44: Total Personal & Other | C44: =SUM(C42:C43)
A46: SAVINGS & INVESTMENTS
A47: Savings | B47: Monthly savings contribution | C47: 0 | E47: Fill in
...

Sheet Savings & Investments
A1: Savings & Investments Tracker
A2: One row per account/pot. Fill in the yellow cells; totals and progress update automatically.
A4: Account / Pot | B4: Type | C4: Starting Balance | D4: Monthly Contribution | E4: Current Balance | F4: Goal Target | G4: Notes
A5: Emergency Fund | B5: Savings | C5: 0 | D5: 0 | E5: 0 | F5: 0
A6: Stocks & Shares ISA | B6: Investment | C6: 0 | D6: 0 | E6: 0 | F6: 0
A7: Pension | B7: Investment | C7: 0 | D7: 0 | E7: 0 | F7: 0
A13: TOTAL | C13: =SUM(C5:C11) | D13: =SUM(D5:D11) | E13: =SUM(E5:E11) | F13: =SUM(F5:F11)

Sheet Upcoming Expenses
A1: Upcoming Expenses
A2: One-off items that crop up as and when they come up (e.g. car MOT, a gift, a repair). Enter Amount as a positive cost — it is automatically treated as money going out. Any item whose date falls in the current Cash Flow Forecast month is pulled in automatically.
A4: Date | B4: Description | C4: Amount | D4: Notes

Sheet Cash Flow Forecast
A1: Cash Flow Forecast
A2: Set Forecast Month + Opening Balance below. Realised Net overrides Forecast Net for a day when filled in. Amounts are pulled from the Budget sheet by Day of Month, plus any items from Upcoming Expenses that fall in this month.
A4: Forecast Month: | B4: 46235 | D4: Opening Balance: | E4: 0
A6: Date | B6: Forecast In | C6: Forecast Out | D6: Upcoming Expenses | E6: Forecast Net | F6: Forecast Balance | G6: Realised Net (manual) | H6: Effective Net | I6: Effective Balance
A7: =IF(1<=DAY(EOMONTH($B$4,0)),DATE(YEAR($B$4),MONTH($B$4),1),"") | B7: =IF(A7="","",SUMIFS(Budget!$C$5:$C$56,Budget!$A$5:$A$56,"Income",Budget!$D$5:$D$56,1)) | C7: =IF(A7="","",SUMIFS(Budget!$C$5:$C$56,Budget!$A$5:$A$56,"<>Income",Budget!$D$5:$D$56,1)) | D7: =IF(A7="","",-SUMIFS('Upcoming Expenses'!$C$5:$C$64,'Upcoming Expenses'!$A$5:$A$64,A7)) | E7: =IF(A7="","",B7-C7+D7) | F7: =IF(A7="","",$E$4+E7) | H7: =IF(A7="","",IF(G7<>"",G7,E7)) | I7: =IF(A7="","",$E$4+H7)
A8: =IF(2<=DAY(EOMONTH($B$4,0)),DATE(YEAR($B$4),MONTH($B$4),2),"") | B8: =IF(A8="","",SUMIFS(Budget!$C$5:$C$56,Budget!$A$5:$A$56,"Income",Budget!$D$5:$D$56,2)) | C8: =IF(A8="","",SUMIFS(Budget!$C$5:$C$56,Budget!$A$5:$A$56,"<>Income",Budget!$D$5:$D$56,2)) | D8: =IF(A8="","",-SUMIFS('Upcoming Expenses'!$C$5:$C$64,'Upcoming Expenses'!$A$5:$A$64,A8)) | E8: =IF(A8="","",B8-C8+D8) | F8: =IF(A8="","",F7+E8) | H8: =IF(A8="","",IF(G8<>"",G8,E8)) | I8: =IF(A8="","",I7+H8)
A9: =IF(3<=DAY(EOMONTH($B$4,0)),DATE(YEAR($B$4),MONTH($B$4),3),"") | B9: =IF(A9="","",SUMIFS(Budget!$C$5:$C$56,Budget!$A$5:$A$56,"Income",Budget!$D$5:$D$56,3)) | C9: =IF(A9="","",SUMIFS(Budget!$C$5:$C$56,Budget!$A$5:$A$56,"<>Income",Budget!$D$5:$D$56,3)) | D9: =IF(A9="","",-SUMIFS('Upcoming Expenses'!$C$5:$C$64,'Upcoming Expenses'!$A$5:$A$64,A9)) | E9: =IF(A9="","",B9-C9+D9) | F9: =IF(A9="","",F8+E9) | H9: =IF(A9="","",IF(G9<>"",G9,E9)) | I9: =IF(A9="","",I8+H9)
A10: =IF(4<=DAY(EOMONTH($B$4,0)),DATE(YEAR($B$4),MONTH($B$4),4),"") | B10: =IF(A10="","",SUMIFS(Budget!$C$5:$C$56,Budget!$A$5:$A$56,"Income",Budget!$D$5:$D$56,4)) | C10: =IF(A10="","",SUMIFS(Budget!$C$5:$C$56,Budget!$A$5:$A$56,"<>Income",Budget!$D$5:$D$56,4)) | D10: =IF(A10="","",-SUMIFS('Upcoming Expenses'!$C$5:$C$64,'Upcoming Expenses'!$A$5:$A$64,A10)) | E10: =IF(A10="","",B10-C10+D10) | F10: =IF(A10="","",F9+E10) | H10: =IF(A10="","",IF(G10<>"",G10,E10)) | I10: =IF(A10="","",I9+H10)
A11: =IF(5<=DAY(EOMONTH($B$4,0)),DATE(YEAR($B$4),MONTH($B$4),5),"") | B11: =IF(A11="","",SUMIFS(Budget!$C$5:$C$56,Budget!$A$5:$A$56,"Income",Budget!$D$5:$D$56,5)) | C11: =IF(A11="","",SUMIFS(Budget!$C$5:$C$56,Budget!$A$5:$A$56,"<>Income",Budget!$D$5:$D$56,5)) | D11: =IF(A11="","",-SUMIFS('Upcoming Expenses'!$C$5:$C$64,'Upcoming Expenses'!$A$5:$A$64,A11)) | E11: =IF(A11="","",B11-C11+D11) | F11: =IF(A11="","",F10+E11) | H11: =IF(A11="","",IF(G11<>"",G11,E11)) | I11: =IF(A11="","",I10+H11)
A12: =IF(6<=DAY(EOMONTH($B$4,0)),DATE(YEAR($B$4),MONTH($B$4),6),"") | B12: =IF(A12="","",SUMIFS(Budget!$C$5:$C$56,Budget!$A$5:$A$56,"Income",Budget!$D$5:$D$56,6)) | C12: =IF(A12="","",SUMIFS(Budget!$C$5:$C$56,Budget!$A$5:$A$56,"<>Income",Budget!$D$5:$D$56,6)) | D12: =IF(A12="","",-SUMIFS('Upcoming Expenses'!$C$5:$C$64,'Upcoming Expenses'!$A$5:$A$64,A12)) | E12: =IF(A12="","",B12-C12+D12) | F12: =IF(A12="","",F11+E12) | H12: =IF(A12="","",IF(G12<>"",G12,E12)) | I12: =IF(A12="","",I11+H12)
A13: =IF(7<=DAY(EOMONTH($B$4,0)),DATE(YEAR($B$4),MONTH($B$4),7),"") | B13: =IF(A13="","",SUMIFS(Budget!$C$5:$C$56,Budget!$A$5:$A$56,"Income",Budget!$D$5:$D$56,7)) | C13: =IF(A13="","",SUMIFS(Budget!$C$5:$C$56,Budget!$A$5:$A$56,"<>Income",Budget!$D$5:$D$56,7)) | D13: =IF(A13="","",-SUMIFS('Upcoming Expenses'!$C$5:$C$64,'Upcoming Expenses'!$A$5:$A$64,A13)) | E13: =IF(A13="","",B13-C13+D13) | F13: =IF(A13="","",F12+E13) | H13: =IF(A13="","",IF(G13<>"",G13,E13)) | I13: =IF(A13="","",I12+H13)
A14: =IF(8<=DAY(EOMONTH($B$4,0)),DATE(YEAR($B$4),MONTH($B$4),8),"") | B14: =IF(A14="","",SUMIFS(Budget!$C$5:$C$56,Budget!$A$5:$A$56,"Income",Budget!$D$5:$D$56,8)) | C14: =IF(A14="","",SUMIFS(Budget!$C$5:$C$56,Budget!$A$5:$A$56,"<>Income",Budget!$D$5:$D$56,8)) | D14: =IF(A14="","",-SUMIFS('Upcoming Expenses'!$C$5:$C$64,'Upcoming Expenses'!$A$5:$A$64,A14)) | E14: =IF(A14="","",B14-C14+D14) | F14: =IF(A14="","",F13+E14) | H14: =IF(A14="","",IF(G14<>"",G14,E14)) | I14: =IF(A14="","",I13+H14)
A15: =IF(9<=DAY(EOMONTH($B$4,0)),DATE(YEAR($B$4),MONTH($B$4),9),"") | B15: =IF(A15="","",SUMIFS(Budget!$C$5:$C$56,Budget!$A$5:$A$56,"Income",Budget!$D$5:$D$56,9)) | C15: =IF(A15="","",SUMIFS(Budget!$C$5:$C$56,Budget!$A$5:$A$56,"<>Income",Budget!$D$5:$D$56,9)) | D15: =IF(A15="","",-SUMIFS('Upcoming Expenses'!$C$5:$C$64,'Upcoming Expenses'!$A$5:$A$64,A15)) | E15: =IF(A15="","",B15-C15+D15) | F15: =IF(A15="","",F14+E15) | H15: =IF(A15="","",IF(G15<>"",G15,E15)) | I15: =IF(A15="","",I14+H15)
A16: =IF(10<=DAY(EOMONTH($B$4,0)),DATE(YEAR($B$4),MONTH($B$4),10),"") | B16: =IF(A16="","",SUMIFS(Budget!$C$5:$C$56,Budget!$A$5:$A$56,"Income",Budget!$D$5:$D$56,10)) | C16: =IF(A16="","",SUMIFS(Budget!$C$5:$C$56,Budget!$A$5:$A$56,"<>Income",Budget!$D$5:$D$56,10)) | D16: =IF(A16="","",-SUMIFS('Upcoming Expenses'!$C$5:$C$64,'Upcoming Expenses'!$A$5:$A$64,A16)) | E16: =IF(A16="","",B16-C16+D16) | F16: =IF(A16="","",F15+E16) | H16: =IF(A16="","",IF(G16<>"",G16,E16)) | I16: =IF(A16="","",I15+H16)
A17: =IF(11<=DAY(EOMONTH($B$4,0)),DATE(YEAR($B$4),MONTH($B$4),11),"") | B17: =IF(A17="","",SUMIFS(Budget!$C$5:$C$56,Budget!$A$5:$A$56,"Income",Budget!$D$5:$D$56,11)) | C17: =IF(A17="","",SUMIFS(Budget!$C$5:$C$56,Budget!$A$5:$A$56,"<>Income",Budget!$D$5:$D$56,11)) | D17: =IF(A17="","",-SUMIFS('Upcoming Expenses'!$C$5:$C$64,'Upcoming Expenses'!$A$5:$A$64,A17)) | E17: =IF(A17="","",B17-C17+D17) | F17: =IF(A17="","",F16+E17) | H17: =IF(A17="","",IF(G17<>"",G17,E17)) | I17: =IF(A17="","",I16+H17)
A18: =IF(12<=DAY(EOMONTH($B$4,0)),DATE(YEAR($B$4),MONTH($B$4),12),"") | B18: =IF(A18="","",SUMIFS(Budget!$C$5:$C$56,Budget!$A$5:$A$56,"Income",Budget!$D$5:$D$56,12)) | C18: =IF(A18="","",SUMIFS(Budget!$C$5:$C$56,Budget!$A$5:$A$56,"<>Income",Budget!$D$5:$D$56,12)) | D18: =IF(A18="","",-SUMIFS('Upcoming Expenses'!$C$5:$C$64,'Upcoming Expenses'!$A$5:$A$64,A18)) | E18: =IF(A18="","",B18-C18+D18) | F18: =IF(A18="","",F17+E18) | H18: =IF(A18="","",IF(G18<>"",G18,E18)) | I18: =IF(A18="","",I17+H18)
A19: =IF(13<=DAY(EOMONTH($B$4,0)),DATE(YEAR($B$4),MONTH($B$4),13),"") | B19: =IF(A19="","",SUMIFS(Budget!$C$5:$C$56,Budget!$A$5:$A$56,"Income",Budget!$D$5:$D$56,13)) | C19: =IF(A19="","",SUMIFS(Budget!$C$5:$C$56,Budget!$A$5:$A$56,"<>Income",Budget!$D$5:$D$56,13)) | D19: =IF(A19="","",-SUMIFS('Upcoming Expenses'!$C$5:$C$64,'Upcoming Expenses'!$A$5:$A$64,A19)) | E19: =IF(A19="","",B19-C19+D19) | F19: =IF(A19="","",F18+E19) | H19: =IF(A19="","",IF(G19<>"",G19,E19)) | I19: =IF(A19="","",I18+H19)
A20: =IF(14<=DAY(EOMONTH($B$4,0)),DATE(YEAR($B$4),MONTH($B$4),14),"") | B20: =IF(A20="","",SUMIFS(Budget!$C$5:$C$56,Budget!$A$5:$A$56,"Income",Budget!$D$5:$D$56,14)) | C20: =IF(A20="","",SUMIFS(Budget!$C$5:$C$56,Budget!$A$5:$A$56,"<>Income",Budget!$D$5:$D$56,14)) | D20: =IF(A20="","",-SUMIFS('Upcoming Expenses'!$C$5:$C$64,'Upcoming Expenses'!$A$5:$A$64,A20)) | E20: =IF(A20="","",B20-C20+D20) | F20: =IF(A20="","",F19+E20) | H20: =IF(A20="","",IF(G20<>"",G20,E20)) | I20: =IF(A20="","",I19+H20)
A21: =IF(15<=DAY(EOMONTH($B$4,0)),DATE(YEAR($B$4),MONTH($B$4),15),"") | B21: =IF(A21="","",SUMIFS(Budget!$C$5:$C$56,Budget!$A$5:$A$56,"Income",Budget!$D$5:$D$56,15)) | C21: =IF(A21="","",SUMIFS(Budget!$C$5:$C$56,Budget!$A$5:$A$56,"<>Income",Budget!$D$5:$D$56,15)) | D21: =IF(A21="","",-SUMIFS('Upcoming Expenses'!$C$5:$C$64,'Upcoming Expenses'!$A$5:$A$64,A21)) | E21: =IF(A21="","",B21-C21+D21) | F21: =IF(A21="","",F20+E21) | H21: =IF(A21="","",IF(G21<>"",G21,E21)) | I21: =IF(A21="","",I20+H21)
A22: =IF(16<=DAY(EOMONTH($B$4,0)),DATE(YEAR($B$4),MONTH($B$4),16),"") | B22: =IF(A22="","",SUMIFS(Budget!$C$5:$C$56,Budget!$A$5:$A$56,"Income",Budget!$D$5:$D$56,16)) | C22: =IF(A22="","",SUMIFS(Budget!$C$5:$C$56,Budget!$A$5:$A$56,"<>Income",Budget!$D$5:$D$56,16)) | D22: =IF(A22="","",-SUMIFS('Upcoming Expenses'!$C$5:$C$64,'Upcoming Expenses'!$A$5:$A$64,A22)) | E22: =IF(A22="","",B22-C22+D22) | F22: =IF(A22="","",F21+E22) | H22: =IF(A22="","",IF(G22<>"",G22,E22)) | I22: =IF(A22="","",I21+H22)
A23: =IF(17<=DAY(EOMONTH($B$4,0)),DATE(YEAR($B$4),MONTH($B$4),17),"") | B23: =IF(A23="","",SUMIFS(Budget!$C$5:$C$56,Budget!$A$5:$A$56,"Income",Budget!$D$5:$D$56,17)) | C23: =IF(A23="","",SUMIFS(Budget!$C$5:$C$56,Budget!$A$5:$A$56,"<>Income",Budget!$D$5:$D$56,17)) | D23: =IF(A23="","",-SUMIFS('Upcoming Expenses'!$C$5:$C$64,'Upcoming Expenses'!$A$5:$A$64,A23)) | E23: =IF(A23="","",B23-C23+D23) | F23: =IF(A23="","",F22+E23) | H23: =IF(A23="","",IF(G23<>"",G23,E23)) | I23: =IF(A23="","",I22+H23)
A24: =IF(18<=DAY(EOMONTH($B$4,0)),DATE(YEAR($B$4),MONTH($B$4),18),"") | B24: =IF(A24="","",SUMIFS(Budget!$C$5:$C$56,Budget!$A$5:$A$56,"Income",Budget!$D$5:$D$56,18)) | C24: =IF(A24="","",SUMIFS(Budget!$C$5:$C$56,Budget!$A$5:$A$56,"<>Income",Budget!$D$5:$D$56,18)) | D24: =IF(A24="","",-SUMIFS('Upcoming Expenses'!$C$5:$C$64,'Upcoming Expenses'!$A$5:$A$64,A24)) | E24: =IF(A24="","",B24-C24+D24) | F24: =IF(A24="","",F23+E24) | H24: =IF(A24="","",IF(G24<>"",G24,E24)) | I24: =IF(A24="","",I23+H24)
A25: =IF(19<=DAY(EOMONTH($B$4,0)),DATE(YEAR($B$4),MONTH($B$4),19),"") | B25: =IF(A25="","",SUMIFS(Budget!$C$5:$C$56,Budget!$A$5:$A$56,"Income",Budget!$D$5:$D$56,19)) | C25: =IF(A25="","",SUMIFS(Budget!$C$5:$C$56,Budget!$A$5:$A$56,"<>Income",Budget!$D$5:$D$56,19)) | D25: =IF(A25="","",-SUMIFS('Upcoming Expenses'!$C$5:$C$64,'Upcoming Expenses'!$A$5:$A$64,A25)) | E25: =IF(A25="","",B25-C25+D25) | F25: =IF(A25="","",F24+E25) | H25: =IF(A25="","",IF(G25<>"",G25,E25)) | I25: =IF(A25="","",I24+H25)
A26: =IF(20<=DAY(EOMONTH($B$4,0)),DATE(YEAR($B$4),MONTH($B$4),20),"") | B26: =IF(A26="","",SUMIFS(Budget!$C$5:$C$56,Budget!$A$5:$A$56,"Income",Budget!$D$5:$D$56,20)) | C26: =IF(A26="","",SUMIFS(Budget!$C$5:$C$56,Budget!$A$5:$A$56,"<>Income",Budget!$D$5:$D$56,20)) | D26: =IF(A26="","",-SUMIFS('Upcoming Expenses'!$C$5:$C$64,'Upcoming Expenses'!$A$5:$A$64,A26)) | E26: =IF(A26="","",B26-C26+D26) | F26: =IF(A26="","",F25+E26) | H26: =IF(A26="","",IF(G26<>"",G26,E26)) | I26: =IF(A26="","",I25+H26)
A27: =IF(21<=DAY(EOMONTH($B$4,0)),DATE(YEAR($B$4),MONTH($B$4),21),"") | B27: =IF(A27="","",SUMIFS(Budget!$C$5:$C$56,Budget!$A$5:$A$56,"Income",Budget!$D$5:$D$56,21)) | C27: =IF(A27="","",SUMIFS(Budget!$C$5:$C$56,Budget!$A$5:$A$56,"<>Income",Budget!$D$5:$D$56,21)) | D27: =IF(A27="","",-SUMIFS('Upcoming Expenses'!$C$5:$C$64,'Upcoming Expenses'!$A$5:$A$64,A27)) | E27: =IF(A27="","",B27-C27+D27) | F27: =IF(A27="","",F26+E27) | H27: =IF(A27="","",IF(G27<>"",G27,E27)) | I27: =IF(A27="","",I26+H27)
A28: =IF(22<=DAY(EOMONTH($B$4,0)),DATE(YEAR($B$4),MONTH($B$4),22),"") | B28: =IF(A28="","",SUMIFS(Budget!$C$5:$C$56,Budget!$A$5:$A$56,"Income",Budget!$D$5:$D$56,22)) | C28: =IF(A28="","",SUMIFS(Budget!$C$5:$C$56,Budget!$A$5:$A$56,"<>Income",Budget!$D$5:$D$56,22)) | D28: =IF(A28="","",-SUMIFS('Upcoming Expenses'!$C$5:$C$64,'Upcoming Expenses'!$A$5:$A$64,A28)) | E28: =IF(A28="","",B28-C28+D28) | F28: =IF(A28="","",F27+E28) | H28: =IF(A28="","",IF(G28<>"",G28,E28)) | I28: =IF(A28="","",I27+H28)
A29: =IF(23<=DAY(EOMONTH($B$4,0)),DATE(YEAR($B$4),MONTH($B$4),23),"") | B29: =IF(A29="","",SUMIFS(Budget!$C$5:$C$56,Budget!$A$5:$A$56,"Income",Budget!$D$5:$D$56,23)) | C29: =IF(A29="","",SUMIFS(Budget!$C$5:$C$56,Budget!$A$5:$A$56,"<>Income",Budget!$D$5:$D$56,23)) | D29: =IF(A29="","",-SUMIFS('Upcoming Expenses'!$C$5:$C$64,'Upcoming Expenses'!$A$5:$A$64,A29)) | E29: =IF(A29="","",B29-C29+D29) | F29: =IF(A29="","",F28+E29) | H29: =IF(A29="","",IF(G29<>"",G29,E29)) | I29: =IF(A29="","",I28+H29)
A30: =IF(24<=DAY(EOMONTH($B$4,0)),DATE(YEAR($B$4),MONTH($B$4),24),"") | B30: =IF(A30="","",SUMIFS(Budget!$C$5:$C$56,Budget!$A$5:$A$56,"Income",Budget!$D$5:$D$56,24)) | C30: =IF(A30="","",SUMIFS(Budget!$C$5:$C$56,Budget!$A$5:$A$56,"<>Income",Budget!$D$5:$D$56,24)) | D30: =IF(A30="","",-SUMIFS('Upcoming Expenses'!$C$5:$C$64,'Upcoming Expenses'!$A$5:$A$64,A30)) | E30: =IF(A30="","",B30-C30+D30) | F30: =IF(A30="","",F29+E30) | H30: =IF(A30="","",IF(G30<>"",G30,E30)) | I30: =IF(A30="","",I29+H30)
A31: =IF(25<=DAY(EOMONTH($B$4,0)),DATE(YEAR($B$4),MONTH($B$4),25),"") | B31: =IF(A31="","",SUMIFS(Budget!$C$5:$C$56,Budget!$A$5:$A$56,"Income",Budget!$D$5:$D$56,25)) | C31: =IF(A31="","",SUMIFS(Budget!$C$5:$C$56,Budget!$A$5:$A$56,"<>Income",Budget!$D$5:$D$56,25)) | D31: =IF(A31="","",-SUMIFS('Upcoming Expenses'!$C$5:$C$64,'Upcoming Expenses'!$A$5:$A$64,A31)) | E31: =IF(A31="","",B31-C31+D31) | F31: =IF(A31="","",F30+E31) | H31: =IF(A31="","",IF(G31<>"",G31,E31)) | I31: =IF(A31="","",I30+H31)
A32: =IF(26<=DAY(EOMONTH($B$4,0)),DATE(YEAR($B$4),MONTH($B$4),26),"") | B32: =IF(A32="","",SUMIFS(Budget!$C$5:$C$56,Budget!$A$5:$A$56,"Income",Budget!$D$5:$D$56,26)) | C32: =IF(A32="","",SUMIFS(Budget!$C$5:$C$56,Budget!$A$5:$A$56,"<>Income",Budget!$D$5:$D$56,26)) | D32: =IF(A32="","",-SUMIFS('Upcoming Expenses'!$C$5:$C$64,'Upcoming Expenses'!$A$5:$A$64,A32)) | E32: =IF(A32="","",B32-C32+D32) | F32: =IF(A32="","",F31+E32) | H32: =IF(A32="","",IF(G32<>"",G32,E32)) | I32: =IF(A32="","",I31+H32)
A33: =IF(27<=DAY(EOMONTH($B$4,0)),DATE(YEAR($B$4),MONTH($B$4),27),"") | B33: =IF(A33="","",SUMIFS(Budget!$C$5:$C$56,Budget!$A$5:$A$56,"Income",Budget!$D$5:$D$56,27)) | C33: =IF(A33="","",SUMIFS(Budget!$C$5:$C$56,Budget!$A$5:$A$56,"<>Income",Budget!$D$5:$D$56,27)) | D33: =IF(A33="","",-SUMIFS('Upcoming Expenses'!$C$5:$C$64,'Upcoming Expenses'!$A$5:$A$64,A33)) | E33: =IF(A33="","",B33-C33+D33) | F33: =IF(A33="","",F32+E33) | H33: =IF(A33="","",IF(G33<>"",G33,E33)) | I33: =IF(A33="","",I32+H33)
A34: =IF(28<=DAY(EOMONTH($B$4,0)),DATE(YEAR($B$4),MONTH($B$4),28),"") | B34: =IF(A34="","",SUMIFS(Budget!$C$5:$C$56,Budget!$A$5:$A$56,"Income",Budget!$D$5:$D$56,28)) | C34: =IF(A34="","",SUMIFS(Budget!$C$5:$C$56,Budget!$A$5:$A$56,"<>Income",Budget!$D$5:$D$56,28)) | D34: =IF(A34="","",-SUMIFS('Upcoming Expenses'!$C$5:$C$64,'Upcoming Expenses'!$A$5:$A$64,A34)) | E34: =IF(A34="","",B34-C34+D34) | F34: =IF(A34="","",F33+E34) | H34: =IF(A34="","",IF(G34<>"",G34,E34)) | I34: =IF(A34="","",I33+H34)
A35: =IF(29<=DAY(EOMONTH($B$4,0)),DATE(YEAR($B$4),MONTH($B$4),29),"") | B35: =IF(A35="","",SUMIFS(Budget!$C$5:$C$56,Budget!$A$5:$A$56,"Income",Budget!$D$5:$D$56,29)) | C35: =IF(A35="","",SUMIFS(Budget!$C$5:$C$56,Budget!$A$5:$A$56,"<>Income",Budget!$D$5:$D$56,29)) | D35: =IF(A35="","",-SUMIFS('Upcoming Expenses'!$C$5:$C$64,'Upcoming Expenses'!$A$5:$A$64,A35)) | E35: =IF(A35="","",B35-C35+D35) | F35: =IF(A35="","",F34+E35) | H35: =IF(A35="","",IF(G35<>"",G35,E35)) | I35: =IF(A35="","",I34+H35)
A36: =IF(30<=DAY(EOMONTH($B$4,0)),DATE(YEAR($B$4),MONTH($B$4),30),"") | B36: =IF(A36="","",SUMIFS(Budget!$C$5:$C$56,Budget!$A$5:$A$56,"Income",Budget!$D$5:$D$56,30)) | C36: =IF(A36="","",SUMIFS(Budget!$C$5:$C$56,Budget!$A$5:$A$56,"<>Income",Budget!$D$5:$D$56,30)) | D36: =IF(A36="","",-SUMIFS('Upcoming Expenses'!$C$5:$C$64,'Upcoming Expenses'!$A$5:$A$64,A36)) | E36: =IF(A36="","",B36-C36+D36) | F36: =IF(A36="","",F35+E36) | H36: =IF(A36="","",IF(G36<>"",G36,E36)) | I36: =IF(A36="","",I35+H36)
A37: =IF(31<=DAY(EOMONTH($B$4,0)),DATE(YEAR($B$4),MONTH($B$4),31),"") | B37: =IF(A37="","",SUMIFS(Budget!$C$5:$C$56,Budget!$A$5:$A$56,"Income",Budget!$D$5:$D$56,31)) | C37: =IF(A37="","",SUMIFS(Budget!$C$5:$C$56,Budget!$A$5:$A$56,"<>Income",Budget!$D$5:$D$56,31)) | D37: =IF(A37="","",-SUMIFS('Upcoming Expenses'!$C$5:$C$64,'Upcoming Expenses'!$A$5:$A$64,A37)) | E37: =IF(A37="","",B37-C37+D37) | F37: =IF(A37="","",F36+E37) | H37: =IF(A37="","",IF(G37<>"",G37,E37)) | I37: =IF(A37="","",I36+H37)
A39: Month Closing Balance (Forecast): | C39: =LOOKUP(2,1/($A$7:$A$37<>""),$F$7:$F$37)
A40: Month Closing Balance (Effective): | C40: =LOOKUP(2,1/($A$7:$A$37<>""),$I$7:$I$37)
